[2023-12-03 18:10:57,829] {taskinstance.py:1159} INFO - Dependencies all met for <TaskInstance: dag_automation_daily.running_automation manual__2023-12-03T18:05:49.653907+00:00 [queued]>
[2023-12-03 18:10:57,846] {taskinstance.py:1159} INFO - Dependencies all met for <TaskInstance: dag_automation_daily.running_automation manual__2023-12-03T18:05:49.653907+00:00 [queued]>
[2023-12-03 18:10:57,846] {taskinstance.py:1356} INFO - 
--------------------------------------------------------------------------------
[2023-12-03 18:10:57,846] {taskinstance.py:1357} INFO - Starting attempt 2 of 2
[2023-12-03 18:10:57,847] {taskinstance.py:1358} INFO - 
--------------------------------------------------------------------------------
[2023-12-03 18:10:57,875] {taskinstance.py:1377} INFO - Executing <Task(BashOperator): running_automation> on 2023-12-03 18:05:49.653907+00:00
[2023-12-03 18:10:57,883] {standard_task_runner.py:52} INFO - Started process 458 to run task
[2023-12-03 18:10:57,888] {standard_task_runner.py:79} INFO - Running: ['***', 'tasks', 'run', 'dag_automation_daily', 'running_automation', 'manual__2023-12-03T18:05:49.653907+00:00', '--job-id', '41', '--raw', '--subdir', 'DAGS_FOLDER/dag.py', '--cfg-path', '/tmp/tmp8xs0ah7k', '--error-file', '/tmp/tmp6fz1prei']
[2023-12-03 18:10:57,890] {standard_task_runner.py:80} INFO - Job 41: Subtask running_automation
[2023-12-03 18:10:58,006] {task_command.py:369} INFO - Running <TaskInstance: dag_automation_daily.running_automation manual__2023-12-03T18:05:49.653907+00:00 [running]> on host c9140d11a0a8
[2023-12-03 18:10:58,205] {taskinstance.py:1571} INFO - Exporting the following env vars:
AIRFLOW_CTX_DAG_EMAIL=sebastiancahyoardhiiswara@gmail.com
AIRFLOW_CTX_DAG_OWNER=***
AIRFLOW_CTX_DAG_ID=dag_automation_daily
AIRFLOW_CTX_TASK_ID=running_automation
AIRFLOW_CTX_EXECUTION_DATE=2023-12-03T18:05:49.653907+00:00
AIRFLOW_CTX_TRY_NUMBER=2
AIRFLOW_CTX_DAG_RUN_ID=manual__2023-12-03T18:05:49.653907+00:00
[2023-12-03 18:10:58,207] {subprocess.py:62} INFO - Tmp dir root location: 
 /tmp
[2023-12-03 18:10:58,209] {subprocess.py:74} INFO - Running command: ['bash', '-c', 'python codes/automation.py']
[2023-12-03 18:10:58,226] {subprocess.py:85} INFO - Output:
[2023-12-03 18:11:02,198] {subprocess.py:92} INFO - (psycopg2.errors.UniqueViolation) duplicate key value violates unique constraint "dim_province_pkey"
[2023-12-03 18:11:02,199] {subprocess.py:92} INFO - DETAIL:  Key (province_id)=(32) already exists.
[2023-12-03 18:11:02,199] {subprocess.py:92} INFO - 
[2023-12-03 18:11:02,200] {subprocess.py:92} INFO - [SQL: INSERT INTO dim_province (province_id, province_name) VALUES (%(province_id)s, %(province_name)s)]
[2023-12-03 18:11:02,200] {subprocess.py:92} INFO - [parameters: {'province_id': '32', 'province_name': 'Jawa Barat'}]
[2023-12-03 18:11:02,200] {subprocess.py:92} INFO - (Background on this error at: http://sqlalche.me/e/14/gkpj)
[2023-12-03 18:11:02,202] {subprocess.py:92} INFO - Traceback (most recent call last):
[2023-12-03 18:11:02,202] {subprocess.py:92} INFO -   File "codes/automation.py", line 16, in <module>
[2023-12-03 18:11:02,202] {subprocess.py:92} INFO -     update_dim_province_table(df, credentials_db_postgres, dim_province)
[2023-12-03 18:11:02,202] {subprocess.py:92} INFO -   File "/opt/***/dags/codes/code.py", line 164, in update_dim_province_table
[2023-12-03 18:11:02,203] {subprocess.py:92} INFO -     conn.commit()
[2023-12-03 18:11:02,203] {subprocess.py:92} INFO - AttributeError: 'Connection' object has no attribute 'commit'
[2023-12-03 18:11:02,496] {subprocess.py:96} INFO - Command exited with return code 1
[2023-12-03 18:11:02,548] {taskinstance.py:1889} ERROR - Task failed with exception
Traceback (most recent call last):
  File "/home/airflow/.local/lib/python3.7/site-packages/airflow/operators/bash.py", line 195, in execute
    f'Bash command failed. The command returned a non-zero exit code {result.exit_code}.'
airflow.exceptions.AirflowException: Bash command failed. The command returned a non-zero exit code 1.
[2023-12-03 18:11:02,558] {taskinstance.py:1400} INFO - Marking task as FAILED. dag_id=dag_automation_daily, task_id=running_automation, execution_date=20231203T180549, start_date=20231203T181057, end_date=20231203T181102
[2023-12-03 18:11:02,603] {standard_task_runner.py:97} ERROR - Failed to execute job 41 for task running_automation (Bash command failed. The command returned a non-zero exit code 1.; 458)
[2023-12-03 18:11:02,620] {local_task_job.py:156} INFO - Task exited with return code 1
[2023-12-03 18:11:02,714] {local_task_job.py:273} INFO - 0 downstream tasks scheduled from follow-on schedule check
