[2023-12-03 17:14:20,392] {taskinstance.py:1159} INFO - Dependencies all met for <TaskInstance: dag_automation_daily.running_automation manual__2023-12-03T17:14:13.703056+00:00 [queued]>
[2023-12-03 17:14:20,453] {taskinstance.py:1159} INFO - Dependencies all met for <TaskInstance: dag_automation_daily.running_automation manual__2023-12-03T17:14:13.703056+00:00 [queued]>
[2023-12-03 17:14:20,453] {taskinstance.py:1356} INFO - 
--------------------------------------------------------------------------------
[2023-12-03 17:14:20,453] {taskinstance.py:1357} INFO - Starting attempt 1 of 2
[2023-12-03 17:14:20,454] {taskinstance.py:1358} INFO - 
--------------------------------------------------------------------------------
[2023-12-03 17:14:20,770] {taskinstance.py:1377} INFO - Executing <Task(BashOperator): running_automation> on 2023-12-03 17:14:13.703056+00:00
[2023-12-03 17:14:20,848] {standard_task_runner.py:52} INFO - Started process 534 to run task
[2023-12-03 17:14:20,948] {standard_task_runner.py:79} INFO - Running: ['***', 'tasks', 'run', 'dag_automation_daily', 'running_automation', 'manual__2023-12-03T17:14:13.703056+00:00', '--job-id', '19', '--raw', '--subdir', 'DAGS_FOLDER/dag.py', '--cfg-path', '/tmp/tmp0zw92g_0', '--error-file', '/tmp/tmpq4pcvjna']
[2023-12-03 17:14:20,952] {standard_task_runner.py:80} INFO - Job 19: Subtask running_automation
[2023-12-03 17:14:22,472] {task_command.py:369} INFO - Running <TaskInstance: dag_automation_daily.running_automation manual__2023-12-03T17:14:13.703056+00:00 [running]> on host b69c54045741
[2023-12-03 17:14:22,961] {taskinstance.py:1571} INFO - Exporting the following env vars:
AIRFLOW_CTX_DAG_EMAIL=sebastiancahyoardhiiswara@gmail.com
AIRFLOW_CTX_DAG_OWNER=***
AIRFLOW_CTX_DAG_ID=dag_automation_daily
AIRFLOW_CTX_TASK_ID=running_automation
AIRFLOW_CTX_EXECUTION_DATE=2023-12-03T17:14:13.703056+00:00
AIRFLOW_CTX_TRY_NUMBER=1
AIRFLOW_CTX_DAG_RUN_ID=manual__2023-12-03T17:14:13.703056+00:00
[2023-12-03 17:14:22,974] {subprocess.py:62} INFO - Tmp dir root location: 
 /tmp
[2023-12-03 17:14:22,976] {subprocess.py:74} INFO - Running command: ['bash', '-c', 'python codes/automation.py']
[2023-12-03 17:14:23,063] {subprocess.py:85} INFO - Output:
[2023-12-03 17:14:29,339] {subprocess.py:92} INFO - Traceback (most recent call last):
[2023-12-03 17:14:29,341] {subprocess.py:92} INFO -   File "/home/***/.local/lib/python3.7/site-packages/sqlalchemy/engine/base.py", line 3141, in _wrap_pool_connect
[2023-12-03 17:14:29,341] {subprocess.py:92} INFO -     return fn()
[2023-12-03 17:14:29,342] {subprocess.py:92} INFO -   File "/home/***/.local/lib/python3.7/site-packages/sqlalchemy/pool/base.py", line 301, in connect
[2023-12-03 17:14:29,342] {subprocess.py:92} INFO -     return _ConnectionFairy._checkout(self)
[2023-12-03 17:14:29,343] {subprocess.py:92} INFO -   File "/home/***/.local/lib/python3.7/site-packages/sqlalchemy/pool/base.py", line 755, in _checkout
[2023-12-03 17:14:29,343] {subprocess.py:92} INFO -     fairy = _ConnectionRecord.checkout(pool)
[2023-12-03 17:14:29,344] {subprocess.py:92} INFO -   File "/home/***/.local/lib/python3.7/site-packages/sqlalchemy/pool/base.py", line 419, in checkout
[2023-12-03 17:14:29,344] {subprocess.py:92} INFO -     rec = pool._do_get()
[2023-12-03 17:14:29,344] {subprocess.py:92} INFO -   File "/home/***/.local/lib/python3.7/site-packages/sqlalchemy/pool/impl.py", line 145, in _do_get
[2023-12-03 17:14:29,345] {subprocess.py:92} INFO -     self._dec_overflow()
[2023-12-03 17:14:29,345] {subprocess.py:92} INFO -   File "/home/***/.local/lib/python3.7/site-packages/sqlalchemy/util/langhelpers.py", line 72, in __exit__
[2023-12-03 17:14:29,345] {subprocess.py:92} INFO -     with_traceback=exc_tb,
[2023-12-03 17:14:29,346] {subprocess.py:92} INFO -   File "/home/***/.local/lib/python3.7/site-packages/sqlalchemy/util/compat.py", line 211, in raise_
[2023-12-03 17:14:29,346] {subprocess.py:92} INFO -     raise exception
[2023-12-03 17:14:29,347] {subprocess.py:92} INFO -   File "/home/***/.local/lib/python3.7/site-packages/sqlalchemy/pool/impl.py", line 142, in _do_get
[2023-12-03 17:14:29,347] {subprocess.py:92} INFO -     return self._create_connection()
[2023-12-03 17:14:29,348] {subprocess.py:92} INFO -   File "/home/***/.local/lib/python3.7/site-packages/sqlalchemy/pool/base.py", line 247, in _create_connection
[2023-12-03 17:14:29,357] {subprocess.py:92} INFO -     return _ConnectionRecord(self)
[2023-12-03 17:14:29,359] {subprocess.py:92} INFO -   File "/home/***/.local/lib/python3.7/site-packages/sqlalchemy/pool/base.py", line 362, in __init__
[2023-12-03 17:14:29,359] {subprocess.py:92} INFO -     self.__connect(first_connect_check=True)
[2023-12-03 17:14:29,360] {subprocess.py:92} INFO -   File "/home/***/.local/lib/python3.7/site-packages/sqlalchemy/pool/base.py", line 605, in __connect
[2023-12-03 17:14:29,361] {subprocess.py:92} INFO -     pool.logger.debug("Error on connect(): %s", e)
[2023-12-03 17:14:29,362] {subprocess.py:92} INFO -   File "/home/***/.local/lib/python3.7/site-packages/sqlalchemy/util/langhelpers.py", line 72, in __exit__
[2023-12-03 17:14:29,364] {subprocess.py:92} INFO -     with_traceback=exc_tb,
[2023-12-03 17:14:29,369] {subprocess.py:92} INFO -   File "/home/***/.local/lib/python3.7/site-packages/sqlalchemy/util/compat.py", line 211, in raise_
[2023-12-03 17:14:29,371] {subprocess.py:92} INFO -     raise exception
[2023-12-03 17:14:29,374] {subprocess.py:92} INFO -   File "/home/***/.local/lib/python3.7/site-packages/sqlalchemy/pool/base.py", line 599, in __connect
[2023-12-03 17:14:29,375] {subprocess.py:92} INFO -     connection = pool._invoke_creator(self)
[2023-12-03 17:14:29,378] {subprocess.py:92} INFO -   File "/home/***/.local/lib/python3.7/site-packages/sqlalchemy/engine/create.py", line 578, in connect
[2023-12-03 17:14:29,388] {subprocess.py:92} INFO -     return dialect.connect(*cargs, **cparams)
[2023-12-03 17:14:29,389] {subprocess.py:92} INFO -   File "/home/***/.local/lib/python3.7/site-packages/sqlalchemy/engine/default.py", line 583, in connect
[2023-12-03 17:14:29,390] {subprocess.py:92} INFO -     return self.dbapi.connect(*cargs, **cparams)
[2023-12-03 17:14:29,394] {subprocess.py:92} INFO -   File "/home/***/.local/lib/python3.7/site-packages/psycopg2/__init__.py", line 122, in connect
[2023-12-03 17:14:29,395] {subprocess.py:92} INFO -     conn = _connect(dsn, connection_factory=connection_factory, **kwasync)
[2023-12-03 17:14:29,396] {subprocess.py:92} INFO - psycopg2.OperationalError: connection to server at "postgres-db" (192.168.228.6), port 5432 failed: FATAL:  password authentication failed for user "***"
[2023-12-03 17:14:29,397] {subprocess.py:92} INFO - 
[2023-12-03 17:14:29,398] {subprocess.py:92} INFO - 
[2023-12-03 17:14:29,398] {subprocess.py:92} INFO - The above exception was the direct cause of the following exception:
[2023-12-03 17:14:29,402] {subprocess.py:92} INFO - 
[2023-12-03 17:14:29,403] {subprocess.py:92} INFO - Traceback (most recent call last):
[2023-12-03 17:14:29,404] {subprocess.py:92} INFO -   File "codes/automation.py", line 10, in <module>
[2023-12-03 17:14:29,405] {subprocess.py:92} INFO -     ) = generate_schema_dwh(credentials_db_postgres)
[2023-12-03 17:14:29,407] {subprocess.py:92} INFO -   File "/opt/***/dags/codes/code.py", line 105, in generate_schema_dwh
[2023-12-03 17:14:29,407] {subprocess.py:92} INFO -     metadata_obj.create_all(engine, checkfirst=True)
[2023-12-03 17:14:29,407] {subprocess.py:92} INFO -   File "/home/***/.local/lib/python3.7/site-packages/sqlalchemy/sql/schema.py", line 4745, in create_all
[2023-12-03 17:14:29,408] {subprocess.py:92} INFO -     ddl.SchemaGenerator, self, checkfirst=checkfirst, tables=tables
[2023-12-03 17:14:29,413] {subprocess.py:92} INFO -   File "/home/***/.local/lib/python3.7/site-packages/sqlalchemy/engine/base.py", line 3007, in _run_ddl_visitor
[2023-12-03 17:14:29,413] {subprocess.py:92} INFO -     with self.begin() as conn:
[2023-12-03 17:14:29,413] {subprocess.py:92} INFO -   File "/home/***/.local/lib/python3.7/site-packages/sqlalchemy/engine/base.py", line 2923, in begin
[2023-12-03 17:14:29,414] {subprocess.py:92} INFO -     conn = self.connect(close_with_result=close_with_result)
[2023-12-03 17:14:29,414] {subprocess.py:92} INFO -   File "/home/***/.local/lib/python3.7/site-packages/sqlalchemy/engine/base.py", line 3095, in connect
[2023-12-03 17:14:29,414] {subprocess.py:92} INFO -     return self._connection_cls(self, close_with_result=close_with_result)
[2023-12-03 17:14:29,415] {subprocess.py:92} INFO -   File "/home/***/.local/lib/python3.7/site-packages/sqlalchemy/engine/base.py", line 91, in __init__
[2023-12-03 17:14:29,415] {subprocess.py:92} INFO -     else engine.raw_connection()
[2023-12-03 17:14:29,416] {subprocess.py:92} INFO -   File "/home/***/.local/lib/python3.7/site-packages/sqlalchemy/engine/base.py", line 3174, in raw_connection
[2023-12-03 17:14:29,416] {subprocess.py:92} INFO -     return self._wrap_pool_connect(self.pool.connect, _connection)
[2023-12-03 17:14:29,417] {subprocess.py:92} INFO -   File "/home/***/.local/lib/python3.7/site-packages/sqlalchemy/engine/base.py", line 3145, in _wrap_pool_connect
[2023-12-03 17:14:29,417] {subprocess.py:92} INFO -     e, dialect, self
[2023-12-03 17:14:29,418] {subprocess.py:92} INFO -   File "/home/***/.local/lib/python3.7/site-packages/sqlalchemy/engine/base.py", line 2004, in _handle_dbapi_exception_noconnection
[2023-12-03 17:14:29,420] {subprocess.py:92} INFO -     sqlalchemy_exception, with_traceback=exc_info[2], from_=e
[2023-12-03 17:14:29,420] {subprocess.py:92} INFO -   File "/home/***/.local/lib/python3.7/site-packages/sqlalchemy/util/compat.py", line 211, in raise_
[2023-12-03 17:14:29,421] {subprocess.py:92} INFO -     raise exception
[2023-12-03 17:14:29,421] {subprocess.py:92} INFO -   File "/home/***/.local/lib/python3.7/site-packages/sqlalchemy/engine/base.py", line 3141, in _wrap_pool_connect
[2023-12-03 17:14:29,421] {subprocess.py:92} INFO -     return fn()
[2023-12-03 17:14:29,422] {subprocess.py:92} INFO -   File "/home/***/.local/lib/python3.7/site-packages/sqlalchemy/pool/base.py", line 301, in connect
[2023-12-03 17:14:29,422] {subprocess.py:92} INFO -     return _ConnectionFairy._checkout(self)
[2023-12-03 17:14:29,422] {subprocess.py:92} INFO -   File "/home/***/.local/lib/python3.7/site-packages/sqlalchemy/pool/base.py", line 755, in _checkout
[2023-12-03 17:14:29,423] {subprocess.py:92} INFO -     fairy = _ConnectionRecord.checkout(pool)
[2023-12-03 17:14:29,423] {subprocess.py:92} INFO -   File "/home/***/.local/lib/python3.7/site-packages/sqlalchemy/pool/base.py", line 419, in checkout
[2023-12-03 17:14:29,423] {subprocess.py:92} INFO -     rec = pool._do_get()
[2023-12-03 17:14:29,423] {subprocess.py:92} INFO -   File "/home/***/.local/lib/python3.7/site-packages/sqlalchemy/pool/impl.py", line 145, in _do_get
[2023-12-03 17:14:29,424] {subprocess.py:92} INFO -     self._dec_overflow()
[2023-12-03 17:14:29,424] {subprocess.py:92} INFO -   File "/home/***/.local/lib/python3.7/site-packages/sqlalchemy/util/langhelpers.py", line 72, in __exit__
[2023-12-03 17:14:29,424] {subprocess.py:92} INFO -     with_traceback=exc_tb,
[2023-12-03 17:14:29,425] {subprocess.py:92} INFO -   File "/home/***/.local/lib/python3.7/site-packages/sqlalchemy/util/compat.py", line 211, in raise_
[2023-12-03 17:14:29,425] {subprocess.py:92} INFO -     raise exception
[2023-12-03 17:14:29,425] {subprocess.py:92} INFO -   File "/home/***/.local/lib/python3.7/site-packages/sqlalchemy/pool/impl.py", line 142, in _do_get
[2023-12-03 17:14:29,426] {subprocess.py:92} INFO -     return self._create_connection()
[2023-12-03 17:14:29,426] {subprocess.py:92} INFO -   File "/home/***/.local/lib/python3.7/site-packages/sqlalchemy/pool/base.py", line 247, in _create_connection
[2023-12-03 17:14:29,426] {subprocess.py:92} INFO -     return _ConnectionRecord(self)
[2023-12-03 17:14:29,427] {subprocess.py:92} INFO -   File "/home/***/.local/lib/python3.7/site-packages/sqlalchemy/pool/base.py", line 362, in __init__
[2023-12-03 17:14:29,427] {subprocess.py:92} INFO -     self.__connect(first_connect_check=True)
[2023-12-03 17:14:29,427] {subprocess.py:92} INFO -   File "/home/***/.local/lib/python3.7/site-packages/sqlalchemy/pool/base.py", line 605, in __connect
[2023-12-03 17:14:29,428] {subprocess.py:92} INFO -     pool.logger.debug("Error on connect(): %s", e)
[2023-12-03 17:14:29,428] {subprocess.py:92} INFO -   File "/home/***/.local/lib/python3.7/site-packages/sqlalchemy/util/langhelpers.py", line 72, in __exit__
[2023-12-03 17:14:29,429] {subprocess.py:92} INFO -     with_traceback=exc_tb,
[2023-12-03 17:14:29,429] {subprocess.py:92} INFO -   File "/home/***/.local/lib/python3.7/site-packages/sqlalchemy/util/compat.py", line 211, in raise_
[2023-12-03 17:14:29,429] {subprocess.py:92} INFO -     raise exception
[2023-12-03 17:14:29,430] {subprocess.py:92} INFO -   File "/home/***/.local/lib/python3.7/site-packages/sqlalchemy/pool/base.py", line 599, in __connect
[2023-12-03 17:14:29,430] {subprocess.py:92} INFO -     connection = pool._invoke_creator(self)
[2023-12-03 17:14:29,430] {subprocess.py:92} INFO -   File "/home/***/.local/lib/python3.7/site-packages/sqlalchemy/engine/create.py", line 578, in connect
[2023-12-03 17:14:29,430] {subprocess.py:92} INFO -     return dialect.connect(*cargs, **cparams)
[2023-12-03 17:14:29,431] {subprocess.py:92} INFO -   File "/home/***/.local/lib/python3.7/site-packages/sqlalchemy/engine/default.py", line 583, in connect
[2023-12-03 17:14:29,431] {subprocess.py:92} INFO -     return self.dbapi.connect(*cargs, **cparams)
[2023-12-03 17:14:29,432] {subprocess.py:92} INFO -   File "/home/***/.local/lib/python3.7/site-packages/psycopg2/__init__.py", line 122, in connect
[2023-12-03 17:14:29,433] {subprocess.py:92} INFO -     conn = _connect(dsn, connection_factory=connection_factory, **kwasync)
[2023-12-03 17:14:29,434] {subprocess.py:92} INFO - sqlalchemy.exc.OperationalError: (psycopg2.OperationalError) connection to server at "postgres-db" (192.168.228.6), port 5432 failed: FATAL:  password authentication failed for user "***"
[2023-12-03 17:14:29,434] {subprocess.py:92} INFO - 
[2023-12-03 17:14:29,435] {subprocess.py:92} INFO - (Background on this error at: http://sqlalche.me/e/14/e3q8)
[2023-12-03 17:14:29,724] {subprocess.py:96} INFO - Command exited with return code 1
[2023-12-03 17:14:29,780] {taskinstance.py:1889} ERROR - Task failed with exception
Traceback (most recent call last):
  File "/home/airflow/.local/lib/python3.7/site-packages/airflow/operators/bash.py", line 195, in execute
    f'Bash command failed. The command returned a non-zero exit code {result.exit_code}.'
airflow.exceptions.AirflowException: Bash command failed. The command returned a non-zero exit code 1.
[2023-12-03 17:14:29,796] {taskinstance.py:1400} INFO - Marking task as UP_FOR_RETRY. dag_id=dag_automation_daily, task_id=running_automation, execution_date=20231203T171413, start_date=20231203T171420, end_date=20231203T171429
[2023-12-03 17:14:29,843] {standard_task_runner.py:97} ERROR - Failed to execute job 19 for task running_automation (Bash command failed. The command returned a non-zero exit code 1.; 534)
[2023-12-03 17:14:29,874] {local_task_job.py:156} INFO - Task exited with return code 1
[2023-12-03 17:14:29,949] {local_task_job.py:273} INFO - 0 downstream tasks scheduled from follow-on schedule check
