[2023-11-30 11:17:23,384] {taskinstance.py:1159} INFO - Dependencies all met for <TaskInstance: final_project_3.running_automation_2 manual__2023-11-30T11:17:17.082708+00:00 [queued]>
[2023-11-30 11:17:23,409] {taskinstance.py:1159} INFO - Dependencies all met for <TaskInstance: final_project_3.running_automation_2 manual__2023-11-30T11:17:17.082708+00:00 [queued]>
[2023-11-30 11:17:23,410] {taskinstance.py:1356} INFO - 
--------------------------------------------------------------------------------
[2023-11-30 11:17:23,411] {taskinstance.py:1357} INFO - Starting attempt 1 of 4
[2023-11-30 11:17:23,411] {taskinstance.py:1358} INFO - 
--------------------------------------------------------------------------------
[2023-11-30 11:17:23,449] {taskinstance.py:1377} INFO - Executing <Task(BashOperator): running_automation_2> on 2023-11-30 11:17:17.082708+00:00
[2023-11-30 11:17:23,479] {standard_task_runner.py:52} INFO - Started process 4977 to run task
[2023-11-30 11:17:23,487] {standard_task_runner.py:79} INFO - Running: ['***', 'tasks', 'run', 'final_project_3', 'running_automation_2', 'manual__2023-11-30T11:17:17.082708+00:00', '--job-id', '44', '--raw', '--subdir', 'DAGS_FOLDER/dag_final.py', '--cfg-path', '/tmp/tmpk081s33r', '--error-file', '/tmp/tmpalud1hbx']
[2023-11-30 11:17:23,488] {standard_task_runner.py:80} INFO - Job 44: Subtask running_automation_2
[2023-11-30 11:17:23,948] {task_command.py:369} INFO - Running <TaskInstance: final_project_3.running_automation_2 manual__2023-11-30T11:17:17.082708+00:00 [running]> on host 8e6e0b239644
[2023-11-30 11:17:24,233] {taskinstance.py:1571} INFO - Exporting the following env vars:
AIRFLOW_CTX_DAG_EMAIL=sebastiancahyoardhiiswara@gmail.com
AIRFLOW_CTX_DAG_OWNER=***
AIRFLOW_CTX_DAG_ID=final_project_3
AIRFLOW_CTX_TASK_ID=running_automation_2
AIRFLOW_CTX_EXECUTION_DATE=2023-11-30T11:17:17.082708+00:00
AIRFLOW_CTX_TRY_NUMBER=1
AIRFLOW_CTX_DAG_RUN_ID=manual__2023-11-30T11:17:17.082708+00:00
[2023-11-30 11:17:24,235] {subprocess.py:62} INFO - Tmp dir root location: 
 /tmp
[2023-11-30 11:17:24,236] {subprocess.py:74} INFO - Running command: ['bash', '-c', 'python automation.py']
[2023-11-30 11:17:24,254] {subprocess.py:85} INFO - Output:
[2023-11-30 11:17:25,749] {subprocess.py:92} INFO - Traceback (most recent call last):
[2023-11-30 11:17:25,750] {subprocess.py:92} INFO -   File "/home/***/.local/lib/python3.7/site-packages/sqlalchemy/engine/base.py", line 3141, in _wrap_pool_connect
[2023-11-30 11:17:25,750] {subprocess.py:92} INFO -     return fn()
[2023-11-30 11:17:25,751] {subprocess.py:92} INFO -   File "/home/***/.local/lib/python3.7/site-packages/sqlalchemy/pool/base.py", line 301, in connect
[2023-11-30 11:17:25,751] {subprocess.py:92} INFO -     return _ConnectionFairy._checkout(self)
[2023-11-30 11:17:25,751] {subprocess.py:92} INFO -   File "/home/***/.local/lib/python3.7/site-packages/sqlalchemy/pool/base.py", line 755, in _checkout
[2023-11-30 11:17:25,752] {subprocess.py:92} INFO -     fairy = _ConnectionRecord.checkout(pool)
[2023-11-30 11:17:25,752] {subprocess.py:92} INFO -   File "/home/***/.local/lib/python3.7/site-packages/sqlalchemy/pool/base.py", line 419, in checkout
[2023-11-30 11:17:25,753] {subprocess.py:92} INFO -     rec = pool._do_get()
[2023-11-30 11:17:25,753] {subprocess.py:92} INFO -   File "/home/***/.local/lib/python3.7/site-packages/sqlalchemy/pool/impl.py", line 145, in _do_get
[2023-11-30 11:17:25,754] {subprocess.py:92} INFO -     self._dec_overflow()
[2023-11-30 11:17:25,754] {subprocess.py:92} INFO -   File "/home/***/.local/lib/python3.7/site-packages/sqlalchemy/util/langhelpers.py", line 72, in __exit__
[2023-11-30 11:17:25,754] {subprocess.py:92} INFO -     with_traceback=exc_tb,
[2023-11-30 11:17:25,755] {subprocess.py:92} INFO -   File "/home/***/.local/lib/python3.7/site-packages/sqlalchemy/util/compat.py", line 211, in raise_
[2023-11-30 11:17:25,755] {subprocess.py:92} INFO -     raise exception
[2023-11-30 11:17:25,756] {subprocess.py:92} INFO -   File "/home/***/.local/lib/python3.7/site-packages/sqlalchemy/pool/impl.py", line 142, in _do_get
[2023-11-30 11:17:25,756] {subprocess.py:92} INFO -     return self._create_connection()
[2023-11-30 11:17:25,757] {subprocess.py:92} INFO -   File "/home/***/.local/lib/python3.7/site-packages/sqlalchemy/pool/base.py", line 247, in _create_connection
[2023-11-30 11:17:25,757] {subprocess.py:92} INFO -     return _ConnectionRecord(self)
[2023-11-30 11:17:25,758] {subprocess.py:92} INFO -   File "/home/***/.local/lib/python3.7/site-packages/sqlalchemy/pool/base.py", line 362, in __init__
[2023-11-30 11:17:25,758] {subprocess.py:92} INFO -     self.__connect(first_connect_check=True)
[2023-11-30 11:17:25,759] {subprocess.py:92} INFO -   File "/home/***/.local/lib/python3.7/site-packages/sqlalchemy/pool/base.py", line 605, in __connect
[2023-11-30 11:17:25,759] {subprocess.py:92} INFO -     pool.logger.debug("Error on connect(): %s", e)
[2023-11-30 11:17:25,760] {subprocess.py:92} INFO -   File "/home/***/.local/lib/python3.7/site-packages/sqlalchemy/util/langhelpers.py", line 72, in __exit__
[2023-11-30 11:17:25,760] {subprocess.py:92} INFO -     with_traceback=exc_tb,
[2023-11-30 11:17:25,761] {subprocess.py:92} INFO -   File "/home/***/.local/lib/python3.7/site-packages/sqlalchemy/util/compat.py", line 211, in raise_
[2023-11-30 11:17:25,761] {subprocess.py:92} INFO -     raise exception
[2023-11-30 11:17:25,762] {subprocess.py:92} INFO -   File "/home/***/.local/lib/python3.7/site-packages/sqlalchemy/pool/base.py", line 599, in __connect
[2023-11-30 11:17:25,762] {subprocess.py:92} INFO -     connection = pool._invoke_creator(self)
[2023-11-30 11:17:25,762] {subprocess.py:92} INFO -   File "/home/***/.local/lib/python3.7/site-packages/sqlalchemy/engine/create.py", line 578, in connect
[2023-11-30 11:17:25,763] {subprocess.py:92} INFO -     return dialect.connect(*cargs, **cparams)
[2023-11-30 11:17:25,763] {subprocess.py:92} INFO -   File "/home/***/.local/lib/python3.7/site-packages/sqlalchemy/engine/default.py", line 583, in connect
[2023-11-30 11:17:25,764] {subprocess.py:92} INFO -     return self.dbapi.connect(*cargs, **cparams)
[2023-11-30 11:17:25,764] {subprocess.py:92} INFO -   File "/home/***/.local/lib/python3.7/site-packages/psycopg2/__init__.py", line 122, in connect
[2023-11-30 11:17:25,765] {subprocess.py:92} INFO -     conn = _connect(dsn, connection_factory=connection_factory, **kwasync)
[2023-11-30 11:17:25,765] {subprocess.py:92} INFO - psycopg2.OperationalError: connection to server at "0.0.0.0", port 5435 failed: Connection refused
[2023-11-30 11:17:25,766] {subprocess.py:92} INFO - 	Is the server running on that host and accepting TCP/IP connections?
[2023-11-30 11:17:25,766] {subprocess.py:92} INFO - 
[2023-11-30 11:17:25,766] {subprocess.py:92} INFO - 
[2023-11-30 11:17:25,767] {subprocess.py:92} INFO - The above exception was the direct cause of the following exception:
[2023-11-30 11:17:25,767] {subprocess.py:92} INFO - 
[2023-11-30 11:17:25,768] {subprocess.py:92} INFO - Traceback (most recent call last):
[2023-11-30 11:17:25,768] {subprocess.py:92} INFO -   File "automation.py", line 13, in <module>
[2023-11-30 11:17:25,769] {subprocess.py:92} INFO -     ) = generate_schema_dwh(credentials_db_postgres)
[2023-11-30 11:17:25,769] {subprocess.py:92} INFO -   File "/opt/***/dags/code.py", line 125, in generate_schema_dwh
[2023-11-30 11:17:25,770] {subprocess.py:92} INFO -     metadata_obj.create_all(engine, checkfirst=True)
[2023-11-30 11:17:25,770] {subprocess.py:92} INFO -   File "/home/***/.local/lib/python3.7/site-packages/sqlalchemy/sql/schema.py", line 4745, in create_all
[2023-11-30 11:17:25,770] {subprocess.py:92} INFO -     ddl.SchemaGenerator, self, checkfirst=checkfirst, tables=tables
[2023-11-30 11:17:25,771] {subprocess.py:92} INFO -   File "/home/***/.local/lib/python3.7/site-packages/sqlalchemy/engine/base.py", line 3007, in _run_ddl_visitor
[2023-11-30 11:17:25,771] {subprocess.py:92} INFO -     with self.begin() as conn:
[2023-11-30 11:17:25,772] {subprocess.py:92} INFO -   File "/home/***/.local/lib/python3.7/site-packages/sqlalchemy/engine/base.py", line 2923, in begin
[2023-11-30 11:17:25,772] {subprocess.py:92} INFO -     conn = self.connect(close_with_result=close_with_result)
[2023-11-30 11:17:25,773] {subprocess.py:92} INFO -   File "/home/***/.local/lib/python3.7/site-packages/sqlalchemy/engine/base.py", line 3095, in connect
[2023-11-30 11:17:25,773] {subprocess.py:92} INFO -     return self._connection_cls(self, close_with_result=close_with_result)
[2023-11-30 11:17:25,774] {subprocess.py:92} INFO -   File "/home/***/.local/lib/python3.7/site-packages/sqlalchemy/engine/base.py", line 91, in __init__
[2023-11-30 11:17:25,774] {subprocess.py:92} INFO -     else engine.raw_connection()
[2023-11-30 11:17:25,775] {subprocess.py:92} INFO -   File "/home/***/.local/lib/python3.7/site-packages/sqlalchemy/engine/base.py", line 3174, in raw_connection
[2023-11-30 11:17:25,776] {subprocess.py:92} INFO -     return self._wrap_pool_connect(self.pool.connect, _connection)
[2023-11-30 11:17:25,777] {subprocess.py:92} INFO -   File "/home/***/.local/lib/python3.7/site-packages/sqlalchemy/engine/base.py", line 3145, in _wrap_pool_connect
[2023-11-30 11:17:25,777] {subprocess.py:92} INFO -     e, dialect, self
[2023-11-30 11:17:25,779] {subprocess.py:92} INFO -   File "/home/***/.local/lib/python3.7/site-packages/sqlalchemy/engine/base.py", line 2004, in _handle_dbapi_exception_noconnection
[2023-11-30 11:17:25,780] {subprocess.py:92} INFO -     sqlalchemy_exception, with_traceback=exc_info[2], from_=e
[2023-11-30 11:17:25,781] {subprocess.py:92} INFO -   File "/home/***/.local/lib/python3.7/site-packages/sqlalchemy/util/compat.py", line 211, in raise_
[2023-11-30 11:17:25,781] {subprocess.py:92} INFO -     raise exception
[2023-11-30 11:17:25,782] {subprocess.py:92} INFO -   File "/home/***/.local/lib/python3.7/site-packages/sqlalchemy/engine/base.py", line 3141, in _wrap_pool_connect
[2023-11-30 11:17:25,782] {subprocess.py:92} INFO -     return fn()
[2023-11-30 11:17:25,783] {subprocess.py:92} INFO -   File "/home/***/.local/lib/python3.7/site-packages/sqlalchemy/pool/base.py", line 301, in connect
[2023-11-30 11:17:25,783] {subprocess.py:92} INFO -     return _ConnectionFairy._checkout(self)
[2023-11-30 11:17:25,784] {subprocess.py:92} INFO -   File "/home/***/.local/lib/python3.7/site-packages/sqlalchemy/pool/base.py", line 755, in _checkout
[2023-11-30 11:17:25,784] {subprocess.py:92} INFO -     fairy = _ConnectionRecord.checkout(pool)
[2023-11-30 11:17:25,785] {subprocess.py:92} INFO -   File "/home/***/.local/lib/python3.7/site-packages/sqlalchemy/pool/base.py", line 419, in checkout
[2023-11-30 11:17:25,785] {subprocess.py:92} INFO -     rec = pool._do_get()
[2023-11-30 11:17:25,786] {subprocess.py:92} INFO -   File "/home/***/.local/lib/python3.7/site-packages/sqlalchemy/pool/impl.py", line 145, in _do_get
[2023-11-30 11:17:25,787] {subprocess.py:92} INFO -     self._dec_overflow()
[2023-11-30 11:17:25,787] {subprocess.py:92} INFO -   File "/home/***/.local/lib/python3.7/site-packages/sqlalchemy/util/langhelpers.py", line 72, in __exit__
[2023-11-30 11:17:25,788] {subprocess.py:92} INFO -     with_traceback=exc_tb,
[2023-11-30 11:17:25,788] {subprocess.py:92} INFO -   File "/home/***/.local/lib/python3.7/site-packages/sqlalchemy/util/compat.py", line 211, in raise_
[2023-11-30 11:17:25,788] {subprocess.py:92} INFO -     raise exception
[2023-11-30 11:17:25,789] {subprocess.py:92} INFO -   File "/home/***/.local/lib/python3.7/site-packages/sqlalchemy/pool/impl.py", line 142, in _do_get
[2023-11-30 11:17:25,789] {subprocess.py:92} INFO -     return self._create_connection()
[2023-11-30 11:17:25,789] {subprocess.py:92} INFO -   File "/home/***/.local/lib/python3.7/site-packages/sqlalchemy/pool/base.py", line 247, in _create_connection
[2023-11-30 11:17:25,790] {subprocess.py:92} INFO -     return _ConnectionRecord(self)
[2023-11-30 11:17:25,790] {subprocess.py:92} INFO -   File "/home/***/.local/lib/python3.7/site-packages/sqlalchemy/pool/base.py", line 362, in __init__
[2023-11-30 11:17:25,790] {subprocess.py:92} INFO -     self.__connect(first_connect_check=True)
[2023-11-30 11:17:25,791] {subprocess.py:92} INFO -   File "/home/***/.local/lib/python3.7/site-packages/sqlalchemy/pool/base.py", line 605, in __connect
[2023-11-30 11:17:25,792] {subprocess.py:92} INFO -     pool.logger.debug("Error on connect(): %s", e)
[2023-11-30 11:17:25,792] {subprocess.py:92} INFO -   File "/home/***/.local/lib/python3.7/site-packages/sqlalchemy/util/langhelpers.py", line 72, in __exit__
[2023-11-30 11:17:25,793] {subprocess.py:92} INFO -     with_traceback=exc_tb,
[2023-11-30 11:17:25,794] {subprocess.py:92} INFO -   File "/home/***/.local/lib/python3.7/site-packages/sqlalchemy/util/compat.py", line 211, in raise_
[2023-11-30 11:17:25,794] {subprocess.py:92} INFO -     raise exception
[2023-11-30 11:17:25,795] {subprocess.py:92} INFO -   File "/home/***/.local/lib/python3.7/site-packages/sqlalchemy/pool/base.py", line 599, in __connect
[2023-11-30 11:17:25,795] {subprocess.py:92} INFO -     connection = pool._invoke_creator(self)
[2023-11-30 11:17:25,796] {subprocess.py:92} INFO -   File "/home/***/.local/lib/python3.7/site-packages/sqlalchemy/engine/create.py", line 578, in connect
[2023-11-30 11:17:25,796] {subprocess.py:92} INFO -     return dialect.connect(*cargs, **cparams)
[2023-11-30 11:17:25,796] {subprocess.py:92} INFO -   File "/home/***/.local/lib/python3.7/site-packages/sqlalchemy/engine/default.py", line 583, in connect
[2023-11-30 11:17:25,797] {subprocess.py:92} INFO -     return self.dbapi.connect(*cargs, **cparams)
[2023-11-30 11:17:25,798] {subprocess.py:92} INFO -   File "/home/***/.local/lib/python3.7/site-packages/psycopg2/__init__.py", line 122, in connect
[2023-11-30 11:17:25,799] {subprocess.py:92} INFO -     conn = _connect(dsn, connection_factory=connection_factory, **kwasync)
[2023-11-30 11:17:25,799] {subprocess.py:92} INFO - sqlalchemy.exc.OperationalError: (psycopg2.OperationalError) connection to server at "0.0.0.0", port 5435 failed: Connection refused
[2023-11-30 11:17:25,800] {subprocess.py:92} INFO - 	Is the server running on that host and accepting TCP/IP connections?
[2023-11-30 11:17:25,800] {subprocess.py:92} INFO - 
[2023-11-30 11:17:25,804] {subprocess.py:92} INFO - (Background on this error at: http://sqlalche.me/e/14/e3q8)
[2023-11-30 11:17:25,896] {subprocess.py:96} INFO - Command exited with return code 1
[2023-11-30 11:17:25,920] {taskinstance.py:1889} ERROR - Task failed with exception
Traceback (most recent call last):
  File "/home/airflow/.local/lib/python3.7/site-packages/airflow/operators/bash.py", line 195, in execute
    f'Bash command failed. The command returned a non-zero exit code {result.exit_code}.'
airflow.exceptions.AirflowException: Bash command failed. The command returned a non-zero exit code 1.
[2023-11-30 11:17:25,926] {taskinstance.py:1400} INFO - Marking task as UP_FOR_RETRY. dag_id=final_project_3, task_id=running_automation_2, execution_date=20231130T111717, start_date=20231130T111723, end_date=20231130T111725
[2023-11-30 11:17:25,948] {standard_task_runner.py:97} ERROR - Failed to execute job 44 for task running_automation_2 (Bash command failed. The command returned a non-zero exit code 1.; 4977)
[2023-11-30 11:17:25,969] {local_task_job.py:156} INFO - Task exited with return code 1
[2023-11-30 11:17:26,039] {local_task_job.py:273} INFO - 0 downstream tasks scheduled from follow-on schedule check
