[2023-11-30 11:15:26,967] {taskinstance.py:1159} INFO - Dependencies all met for <TaskInstance: final_project_3.running_automation_2 manual__2023-11-30T11:10:15.882968+00:00 [queued]>
[2023-11-30 11:15:27,013] {taskinstance.py:1159} INFO - Dependencies all met for <TaskInstance: final_project_3.running_automation_2 manual__2023-11-30T11:10:15.882968+00:00 [queued]>
[2023-11-30 11:15:27,013] {taskinstance.py:1356} INFO - 
--------------------------------------------------------------------------------
[2023-11-30 11:15:27,014] {taskinstance.py:1357} INFO - Starting attempt 2 of 4
[2023-11-30 11:15:27,014] {taskinstance.py:1358} INFO - 
--------------------------------------------------------------------------------
[2023-11-30 11:15:27,064] {taskinstance.py:1377} INFO - Executing <Task(BashOperator): running_automation_2> on 2023-11-30 11:10:15.882968+00:00
[2023-11-30 11:15:27,193] {standard_task_runner.py:79} INFO - Running: ['***', 'tasks', 'run', 'final_project_3', 'running_automation_2', 'manual__2023-11-30T11:10:15.882968+00:00', '--job-id', '41', '--raw', '--subdir', 'DAGS_FOLDER/dag_final.py', '--cfg-path', '/tmp/tmpu6gf0o3t', '--error-file', '/tmp/tmp8q40ssic']
[2023-11-30 11:15:27,196] {standard_task_runner.py:80} INFO - Job 41: Subtask running_automation_2
[2023-11-30 11:15:27,232] {standard_task_runner.py:52} INFO - Started process 4880 to run task
[2023-11-30 11:15:27,454] {task_command.py:369} INFO - Running <TaskInstance: final_project_3.running_automation_2 manual__2023-11-30T11:10:15.882968+00:00 [running]> on host 8e6e0b239644
[2023-11-30 11:15:28,065] {taskinstance.py:1571} INFO - Exporting the following env vars:
AIRFLOW_CTX_DAG_EMAIL=sebastiancahyoardhiiswara@gmail.com
AIRFLOW_CTX_DAG_OWNER=***
AIRFLOW_CTX_DAG_ID=final_project_3
AIRFLOW_CTX_TASK_ID=running_automation_2
AIRFLOW_CTX_EXECUTION_DATE=2023-11-30T11:10:15.882968+00:00
AIRFLOW_CTX_TRY_NUMBER=2
AIRFLOW_CTX_DAG_RUN_ID=manual__2023-11-30T11:10:15.882968+00:00
[2023-11-30 11:15:28,067] {subprocess.py:62} INFO - Tmp dir root location: 
 /tmp
[2023-11-30 11:15:28,068] {subprocess.py:74} INFO - Running command: ['bash', '-c', 'python automation.py']
[2023-11-30 11:15:28,091] {subprocess.py:85} INFO - Output:
[2023-11-30 11:15:35,106] {subprocess.py:92} INFO - Traceback (most recent call last):
[2023-11-30 11:15:35,110] {subprocess.py:92} INFO -   File "/home/***/.local/lib/python3.7/site-packages/sqlalchemy/engine/base.py", line 3141, in _wrap_pool_connect
[2023-11-30 11:15:35,111] {subprocess.py:92} INFO -     return fn()
[2023-11-30 11:15:35,111] {subprocess.py:92} INFO -   File "/home/***/.local/lib/python3.7/site-packages/sqlalchemy/pool/base.py", line 301, in connect
[2023-11-30 11:15:35,111] {subprocess.py:92} INFO -     return _ConnectionFairy._checkout(self)
[2023-11-30 11:15:35,112] {subprocess.py:92} INFO -   File "/home/***/.local/lib/python3.7/site-packages/sqlalchemy/pool/base.py", line 755, in _checkout
[2023-11-30 11:15:35,112] {subprocess.py:92} INFO -     fairy = _ConnectionRecord.checkout(pool)
[2023-11-30 11:15:35,112] {subprocess.py:92} INFO -   File "/home/***/.local/lib/python3.7/site-packages/sqlalchemy/pool/base.py", line 419, in checkout
[2023-11-30 11:15:35,112] {subprocess.py:92} INFO -     rec = pool._do_get()
[2023-11-30 11:15:35,113] {subprocess.py:92} INFO -   File "/home/***/.local/lib/python3.7/site-packages/sqlalchemy/pool/impl.py", line 145, in _do_get
[2023-11-30 11:15:35,113] {subprocess.py:92} INFO -     self._dec_overflow()
[2023-11-30 11:15:35,113] {subprocess.py:92} INFO -   File "/home/***/.local/lib/python3.7/site-packages/sqlalchemy/util/langhelpers.py", line 72, in __exit__
[2023-11-30 11:15:35,114] {subprocess.py:92} INFO -     with_traceback=exc_tb,
[2023-11-30 11:15:35,114] {subprocess.py:92} INFO -   File "/home/***/.local/lib/python3.7/site-packages/sqlalchemy/util/compat.py", line 211, in raise_
[2023-11-30 11:15:35,114] {subprocess.py:92} INFO -     raise exception
[2023-11-30 11:15:35,114] {subprocess.py:92} INFO -   File "/home/***/.local/lib/python3.7/site-packages/sqlalchemy/pool/impl.py", line 142, in _do_get
[2023-11-30 11:15:35,115] {subprocess.py:92} INFO -     return self._create_connection()
[2023-11-30 11:15:35,116] {subprocess.py:92} INFO -   File "/home/***/.local/lib/python3.7/site-packages/sqlalchemy/pool/base.py", line 247, in _create_connection
[2023-11-30 11:15:35,116] {subprocess.py:92} INFO -     return _ConnectionRecord(self)
[2023-11-30 11:15:35,116] {subprocess.py:92} INFO -   File "/home/***/.local/lib/python3.7/site-packages/sqlalchemy/pool/base.py", line 362, in __init__
[2023-11-30 11:15:35,116] {subprocess.py:92} INFO -     self.__connect(first_connect_check=True)
[2023-11-30 11:15:35,117] {subprocess.py:92} INFO -   File "/home/***/.local/lib/python3.7/site-packages/sqlalchemy/pool/base.py", line 605, in __connect
[2023-11-30 11:15:35,117] {subprocess.py:92} INFO -     pool.logger.debug("Error on connect(): %s", e)
[2023-11-30 11:15:35,118] {subprocess.py:92} INFO -   File "/home/***/.local/lib/python3.7/site-packages/sqlalchemy/util/langhelpers.py", line 72, in __exit__
[2023-11-30 11:15:35,119] {subprocess.py:92} INFO -     with_traceback=exc_tb,
[2023-11-30 11:15:35,119] {subprocess.py:92} INFO -   File "/home/***/.local/lib/python3.7/site-packages/sqlalchemy/util/compat.py", line 211, in raise_
[2023-11-30 11:15:35,120] {subprocess.py:92} INFO -     raise exception
[2023-11-30 11:15:35,121] {subprocess.py:92} INFO -   File "/home/***/.local/lib/python3.7/site-packages/sqlalchemy/pool/base.py", line 599, in __connect
[2023-11-30 11:15:35,121] {subprocess.py:92} INFO -     connection = pool._invoke_creator(self)
[2023-11-30 11:15:35,122] {subprocess.py:92} INFO -   File "/home/***/.local/lib/python3.7/site-packages/sqlalchemy/engine/create.py", line 578, in connect
[2023-11-30 11:15:35,122] {subprocess.py:92} INFO -     return dialect.connect(*cargs, **cparams)
[2023-11-30 11:15:35,122] {subprocess.py:92} INFO -   File "/home/***/.local/lib/python3.7/site-packages/sqlalchemy/engine/default.py", line 583, in connect
[2023-11-30 11:15:35,122] {subprocess.py:92} INFO -     return self.dbapi.connect(*cargs, **cparams)
[2023-11-30 11:15:35,123] {subprocess.py:92} INFO -   File "/home/***/.local/lib/python3.7/site-packages/psycopg2/__init__.py", line 122, in connect
[2023-11-30 11:15:35,123] {subprocess.py:92} INFO -     conn = _connect(dsn, connection_factory=connection_factory, **kwasync)
[2023-11-30 11:15:35,123] {subprocess.py:92} INFO - psycopg2.OperationalError: connection to server at "0.0.0.0", port 5435 failed: Connection refused
[2023-11-30 11:15:35,124] {subprocess.py:92} INFO - 	Is the server running on that host and accepting TCP/IP connections?
[2023-11-30 11:15:35,124] {subprocess.py:92} INFO - 
[2023-11-30 11:15:35,124] {subprocess.py:92} INFO - 
[2023-11-30 11:15:35,125] {subprocess.py:92} INFO - The above exception was the direct cause of the following exception:
[2023-11-30 11:15:35,126] {subprocess.py:92} INFO - 
[2023-11-30 11:15:35,127] {subprocess.py:92} INFO - Traceback (most recent call last):
[2023-11-30 11:15:35,127] {subprocess.py:92} INFO -   File "automation.py", line 13, in <module>
[2023-11-30 11:15:35,127] {subprocess.py:92} INFO -     ) = generate_schema_dwh(credentials_db_postgres)
[2023-11-30 11:15:35,128] {subprocess.py:92} INFO -   File "/opt/***/dags/code.py", line 125, in generate_schema_dwh
[2023-11-30 11:15:35,128] {subprocess.py:92} INFO -     metadata_obj.create_all(engine, checkfirst=True)
[2023-11-30 11:15:35,128] {subprocess.py:92} INFO -   File "/home/***/.local/lib/python3.7/site-packages/sqlalchemy/sql/schema.py", line 4745, in create_all
[2023-11-30 11:15:35,129] {subprocess.py:92} INFO -     ddl.SchemaGenerator, self, checkfirst=checkfirst, tables=tables
[2023-11-30 11:15:35,129] {subprocess.py:92} INFO -   File "/home/***/.local/lib/python3.7/site-packages/sqlalchemy/engine/base.py", line 3007, in _run_ddl_visitor
[2023-11-30 11:15:35,129] {subprocess.py:92} INFO -     with self.begin() as conn:
[2023-11-30 11:15:35,130] {subprocess.py:92} INFO -   File "/home/***/.local/lib/python3.7/site-packages/sqlalchemy/engine/base.py", line 2923, in begin
[2023-11-30 11:15:35,130] {subprocess.py:92} INFO -     conn = self.connect(close_with_result=close_with_result)
[2023-11-30 11:15:35,130] {subprocess.py:92} INFO -   File "/home/***/.local/lib/python3.7/site-packages/sqlalchemy/engine/base.py", line 3095, in connect
[2023-11-30 11:15:35,131] {subprocess.py:92} INFO -     return self._connection_cls(self, close_with_result=close_with_result)
[2023-11-30 11:15:35,131] {subprocess.py:92} INFO -   File "/home/***/.local/lib/python3.7/site-packages/sqlalchemy/engine/base.py", line 91, in __init__
[2023-11-30 11:15:35,131] {subprocess.py:92} INFO -     else engine.raw_connection()
[2023-11-30 11:15:35,131] {subprocess.py:92} INFO -   File "/home/***/.local/lib/python3.7/site-packages/sqlalchemy/engine/base.py", line 3174, in raw_connection
[2023-11-30 11:15:35,132] {subprocess.py:92} INFO -     return self._wrap_pool_connect(self.pool.connect, _connection)
[2023-11-30 11:15:35,132] {subprocess.py:92} INFO -   File "/home/***/.local/lib/python3.7/site-packages/sqlalchemy/engine/base.py", line 3145, in _wrap_pool_connect
[2023-11-30 11:15:35,133] {subprocess.py:92} INFO -     e, dialect, self
[2023-11-30 11:15:35,133] {subprocess.py:92} INFO -   File "/home/***/.local/lib/python3.7/site-packages/sqlalchemy/engine/base.py", line 2004, in _handle_dbapi_exception_noconnection
[2023-11-30 11:15:35,134] {subprocess.py:92} INFO -     sqlalchemy_exception, with_traceback=exc_info[2], from_=e
[2023-11-30 11:15:35,134] {subprocess.py:92} INFO -   File "/home/***/.local/lib/python3.7/site-packages/sqlalchemy/util/compat.py", line 211, in raise_
[2023-11-30 11:15:35,134] {subprocess.py:92} INFO -     raise exception
[2023-11-30 11:15:35,135] {subprocess.py:92} INFO -   File "/home/***/.local/lib/python3.7/site-packages/sqlalchemy/engine/base.py", line 3141, in _wrap_pool_connect
[2023-11-30 11:15:35,135] {subprocess.py:92} INFO -     return fn()
[2023-11-30 11:15:35,135] {subprocess.py:92} INFO -   File "/home/***/.local/lib/python3.7/site-packages/sqlalchemy/pool/base.py", line 301, in connect
[2023-11-30 11:15:35,136] {subprocess.py:92} INFO -     return _ConnectionFairy._checkout(self)
[2023-11-30 11:15:35,136] {subprocess.py:92} INFO -   File "/home/***/.local/lib/python3.7/site-packages/sqlalchemy/pool/base.py", line 755, in _checkout
[2023-11-30 11:15:35,137] {subprocess.py:92} INFO -     fairy = _ConnectionRecord.checkout(pool)
[2023-11-30 11:15:35,138] {subprocess.py:92} INFO -   File "/home/***/.local/lib/python3.7/site-packages/sqlalchemy/pool/base.py", line 419, in checkout
[2023-11-30 11:15:35,138] {subprocess.py:92} INFO -     rec = pool._do_get()
[2023-11-30 11:15:35,138] {subprocess.py:92} INFO -   File "/home/***/.local/lib/python3.7/site-packages/sqlalchemy/pool/impl.py", line 145, in _do_get
[2023-11-30 11:15:35,139] {subprocess.py:92} INFO -     self._dec_overflow()
[2023-11-30 11:15:35,139] {subprocess.py:92} INFO -   File "/home/***/.local/lib/python3.7/site-packages/sqlalchemy/util/langhelpers.py", line 72, in __exit__
[2023-11-30 11:15:35,139] {subprocess.py:92} INFO -     with_traceback=exc_tb,
[2023-11-30 11:15:35,140] {subprocess.py:92} INFO -   File "/home/***/.local/lib/python3.7/site-packages/sqlalchemy/util/compat.py", line 211, in raise_
[2023-11-30 11:15:35,140] {subprocess.py:92} INFO -     raise exception
[2023-11-30 11:15:35,141] {subprocess.py:92} INFO -   File "/home/***/.local/lib/python3.7/site-packages/sqlalchemy/pool/impl.py", line 142, in _do_get
[2023-11-30 11:15:35,141] {subprocess.py:92} INFO -     return self._create_connection()
[2023-11-30 11:15:35,141] {subprocess.py:92} INFO -   File "/home/***/.local/lib/python3.7/site-packages/sqlalchemy/pool/base.py", line 247, in _create_connection
[2023-11-30 11:15:35,141] {subprocess.py:92} INFO -     return _ConnectionRecord(self)
[2023-11-30 11:15:35,142] {subprocess.py:92} INFO -   File "/home/***/.local/lib/python3.7/site-packages/sqlalchemy/pool/base.py", line 362, in __init__
[2023-11-30 11:15:35,142] {subprocess.py:92} INFO -     self.__connect(first_connect_check=True)
[2023-11-30 11:15:35,142] {subprocess.py:92} INFO -   File "/home/***/.local/lib/python3.7/site-packages/sqlalchemy/pool/base.py", line 605, in __connect
[2023-11-30 11:15:35,143] {subprocess.py:92} INFO -     pool.logger.debug("Error on connect(): %s", e)
[2023-11-30 11:15:35,143] {subprocess.py:92} INFO -   File "/home/***/.local/lib/python3.7/site-packages/sqlalchemy/util/langhelpers.py", line 72, in __exit__
[2023-11-30 11:15:35,143] {subprocess.py:92} INFO -     with_traceback=exc_tb,
[2023-11-30 11:15:35,144] {subprocess.py:92} INFO -   File "/home/***/.local/lib/python3.7/site-packages/sqlalchemy/util/compat.py", line 211, in raise_
[2023-11-30 11:15:35,144] {subprocess.py:92} INFO -     raise exception
[2023-11-30 11:15:35,145] {subprocess.py:92} INFO -   File "/home/***/.local/lib/python3.7/site-packages/sqlalchemy/pool/base.py", line 599, in __connect
[2023-11-30 11:15:35,146] {subprocess.py:92} INFO -     connection = pool._invoke_creator(self)
[2023-11-30 11:15:35,147] {subprocess.py:92} INFO -   File "/home/***/.local/lib/python3.7/site-packages/sqlalchemy/engine/create.py", line 578, in connect
[2023-11-30 11:15:35,147] {subprocess.py:92} INFO -     return dialect.connect(*cargs, **cparams)
[2023-11-30 11:15:35,147] {subprocess.py:92} INFO -   File "/home/***/.local/lib/python3.7/site-packages/sqlalchemy/engine/default.py", line 583, in connect
[2023-11-30 11:15:35,147] {subprocess.py:92} INFO -     return self.dbapi.connect(*cargs, **cparams)
[2023-11-30 11:15:35,148] {subprocess.py:92} INFO -   File "/home/***/.local/lib/python3.7/site-packages/psycopg2/__init__.py", line 122, in connect
[2023-11-30 11:15:35,148] {subprocess.py:92} INFO -     conn = _connect(dsn, connection_factory=connection_factory, **kwasync)
[2023-11-30 11:15:35,148] {subprocess.py:92} INFO - sqlalchemy.exc.OperationalError: (psycopg2.OperationalError) connection to server at "0.0.0.0", port 5435 failed: Connection refused
[2023-11-30 11:15:35,149] {subprocess.py:92} INFO - 	Is the server running on that host and accepting TCP/IP connections?
[2023-11-30 11:15:35,149] {subprocess.py:92} INFO - 
[2023-11-30 11:15:35,149] {subprocess.py:92} INFO - (Background on this error at: http://sqlalche.me/e/14/e3q8)
[2023-11-30 11:15:35,466] {subprocess.py:96} INFO - Command exited with return code 1
[2023-11-30 11:15:35,568] {taskinstance.py:1889} ERROR - Task failed with exception
Traceback (most recent call last):
  File "/home/airflow/.local/lib/python3.7/site-packages/airflow/operators/bash.py", line 195, in execute
    f'Bash command failed. The command returned a non-zero exit code {result.exit_code}.'
airflow.exceptions.AirflowException: Bash command failed. The command returned a non-zero exit code 1.
[2023-11-30 11:15:35,596] {taskinstance.py:1400} INFO - Marking task as UP_FOR_RETRY. dag_id=final_project_3, task_id=running_automation_2, execution_date=20231130T111015, start_date=20231130T111526, end_date=20231130T111535
[2023-11-30 11:15:35,716] {standard_task_runner.py:97} ERROR - Failed to execute job 41 for task running_automation_2 (Bash command failed. The command returned a non-zero exit code 1.; 4880)
[2023-11-30 11:15:35,760] {local_task_job.py:156} INFO - Task exited with return code 1
[2023-11-30 11:15:35,860] {local_task_job.py:273} INFO - 0 downstream tasks scheduled from follow-on schedule check
